Workbook
Name IQ_CH: 110000
Name IQ_CQ: 5000
Name IQ_CY: 10000
Name IQ_DAILY: 500000
Name IQ_FH: 100000
Name IQ_FQ: 500
Name IQ_FY: 1000
Name IQ_LTM: 2000
Name IQ_MONTH: 15000
Name IQ_NTM: 6000
Name IQ_WEEK: 50000
Name IQ_YTD: 3000

Sheet Original
A1: Status | B1: Area | C1: Auditable Entity | D1: Auditable Sub - Entity | E1: Area | F1: SOL ID | G1: Accountable Exec. Role (N-1) | H1: Accountable Executive | I1: Business Owner (N-2) | J1: Business Owner (N-3) | K1: Audit Owner | L1: Inherent Risk | M1: Control Environment | N1: Calculated Residual Risk | O1: Original Audit Cycle | P1: Manually Adjusted Residual Risk | Q1: Regulatory | R1: Adjusted Audit Cycle | S1: Manual Override | T1: Last Audit Year | U1: Last Audit Rating | V1: Audit Plan 2022 | W1: Audit Plan 2023 | X1: Audit Plan 2024 | Y1: Audit Plan 2025 | Z1: In CY Audit Plan | AA1: Covered in Last 3 Years | AB1: Comments
A2: Original | B2: Retail Channels | C2: Branches | D2: Ajman | E2: Branches | F2: 019 | G2: MD Business Banking | H2: Dhiraj Kunwar | I2: Saud (Naji) Mohd. | K2: Sangeetha Abraham | L2: Medium | M2: =IF(T2>2017,U2,"N/A") -> Sat | N2: Medium | O2: =IF(Q2="y",1,SUMIFS('Rating Grid'!$D$11:$D$34,'Rating Grid'!$B$11:$B$34,Original!$L$30:$L$172,'Rating Grid'!$C$11:$C$34,Original!$M$30:$M$172)) -> 0 | P2: Low | Q2: N | R2: =IF(O2>S2,O2,S2) -> 0 | T2: 2020 | U2: Sat | V2: =IF($T2+$R2<=2022,"2022","-") -> 2022 | W2: =IF($T2+$R2=2023,"2023","-") -> - | X2: =IF($T2+$R2=2024,"2024","-") -> - | Y2: =IF($T2+$R2=2025,"2025","-") -> - | AA2: =IF($T2>2018,"Y","N") -> Y
A3: Original | B3: Retail Channels | C3: Branches | D3: Al Ain | E3: Branches | F3: 014 | G3: MD Business Banking | H3: Dhiraj Kunwar | I3: Saud (Naji) Mohd. | K3: Sangeetha Abraham | L3: Medium | M3: =IF(T3>2017,U3,"N/A") -> NI | N3: Medium | O3: =IF(Q3="y",1,SUMIFS('Rating Grid'!$D$11:$D$34,'Rating Grid'!$B$11:$B$34,Original!$L$30:$L$172,'Rating Grid'!$C$11:$C$34,Original!$M$30:$M$172)) -> 0 | P3: Medium | Q3: N | R3: =IF(O3>S3,O3,S3) -> 0 | T3: 2021 | U3: NI | V3: =IF($T3+$R3<=2022,"2022","-") -> 2022 | W3: =IF($T3+$R3=2023,"2023","-") -> - | X3: =IF($T3+$R3=2024,"2024","-") -> - | Y3: =IF($T3+$R3=2025,"2025","-") -> - | AA3: =IF($T3>2018,"Y","N") -> Y
A4: Original | B4: Retail Channels | C4: Branches | D4: Al Dhait | E4: Branches | F4: 031 | G4: MD Business Banking | H4: Dhiraj Kunwar | I4: Saud (Naji) Mohd. | K4: Sangeetha Abraham | L4: Medium | M4: =IF(T4>2017,U4,"N/A") -> NI | N4: Low | O4: =IF(Q4="y",1,SUMIFS('Rating Grid'!$D$11:$D$34,'Rating Grid'!$B$11:$B$34,Original!$L$30:$L$172,'Rating Grid'!$C$11:$C$34,Original!$M$30:$M$172)) -> 0 | P4: Medium | Q4: N | R4: =IF(O4>S4,O4,S4) -> 0 | T4: 2021 | U4: NI | V4: =IF($T4+$R4<=2022,"2022","-") -> 2022 | W4: =IF($T4+$R4=2023,"2023","-") -> - | X4: =IF($T4+$R4=2024,"2024","-") -> - | Y4: =IF($T4+$R4=2025,"2025","-") -> - | AA4: =IF($T4>2018,"Y","N") -> Y
A5: Original | B5: Retail Channels | C5: Branches | D5: Al Hamra | E5: Branches | F5: 065 | G5: MD Business Banking | H5: Dhiraj Kunwar | I5: Saud (Naji) Mohd. | K5: Sangeetha Abraham | L5: Medium | M5: =IF(T5>2017,U5,"N/A") -> Sat | N5: Low | O5: =IF(Q5="y",1,SUMIFS('Rating Grid'!$D$11:$D$34,'Rating Grid'!$B$11:$B$34,Original!$L$30:$L$172,'Rating Grid'!$C$11:$C$34,Original!$M$30:$M$172)) -> 0 | P5: Low | Q5: N | R5: =IF(O5>S5,O5,S5) -> 0 | T5: 2019 | U5: Sat | V5: =IF($T5+$R5<=2022,"2022","-") -> 2022 | W5: =IF($T5+$R5=2023,"2023","-") -> - | X5: =IF($T5+$R5=2024,"2024","-") -> - | Y5: =IF($T5+$R5=2025,"2025","-") -> - | AA5: =IF($T5>2018,"Y","N") -> Y
A6: Original | B6: Retail Channels | C6: Branches | D6: Al Kharan | E6: Branches | F6: 008 | G6: MD Business Banking | H6: Dhiraj Kunwar | I6: Saud (Naji) Mohd. | K6: Sangeetha Abraham | L6: Medium | M6: =IF(T6>2017,U6,"N/A") -> NI | N6: Low | O6: =IF(Q6="y",1,SUMIFS('Rating Grid'!$D$11:$D$34,'Rating Grid'!$B$11:$B$34,Original!$L$30:$L$172,'Rating Grid'!$C$11:$C$34,Original!$M$30:$M$172)) -> 0 | P6: Medium | Q6: N | R6: =IF(O6>S6,O6,S6) -> 0 | T6: 2020 | U6: NI | V6: =IF($T6+$R6<=2022,"2022","-") -> 2022 | W6: =IF($T6+$R6=2023,"2023","-") -> - | X6: =IF($T6+$R6=2024,"2024","-") -> - | Y6: =IF($T6+$R6=2025,"2025","-") -> - | AA6: =IF($T6>2018,"Y","N") -> Y
A7: Original | B7: Retail Channels | C7: Branches | D7: Al Madinah | E7: Branches | F7: 005 | G7: MD Business Banking | H7: Dhiraj Kunwar | I7: Saud (Naji) Mohd. | K7: Sangeetha Abraham | L7: Medium | M7: =IF(T7>2017,U7,"N/A") -> NI | N7: Medium | O7: =IF(Q7="y",1,SUMIFS('Rating Grid'!$D$11:$D$34,'Rating Grid'!$B$11:$B$34,Original!$L$30:$L$172,'Rating Grid'!$C$11:$C$34,Original!$M$30:$M$172)) -> 0 | P7: Medium | Q7: N | R7: =IF(O7>S7,O7,S7) -> 0 | T7: 2020 | U7: NI | V7: =IF($T7+$R7<=2022,"2022","-") -> 2022 | W7: =IF($T7+$R7=2023,"2023","-") -> - | X7: =IF($T7+$R7=2024,"2024","-") -> - | Y7: =IF($T7+$R7=2025,"2025","-") -> - | Z7: Y | AA7: =IF($T7>2018,"Y","N") -> Y | AB7: Q1 2022
A8: Original | B8: Retail Channels | C8: Branches | D8: Al Mannai | E8: Branches | F8: 016 | G8: MD Business Banking | H8: Dhiraj Kunwar | I8: Saud (Naji) Mohd. | K8: Sangeetha Abraham | L8: Medium | M8: =IF(T8>2017,U8,"N/A") -> NI | N8: Low | O8: =IF(Q8="y",1,SUMIFS('Rating Grid'!$D$11:$D$34,'Rating Grid'!$B$11:$B$34,Original!$L$30:$L$172,'Rating Grid'!$C$11:$C$34,Original!$M$30:$M$172)) -> 0 | P8: Medium | Q8: N | R8: =IF(O8>S8,O8,S8) -> 0 | T8: 2021 | U8: NI | V8: =IF($T8+$R8<=2022,"2022","-") -> 2022 | W8: =IF($T8+$R8=2023,"2023","-") -> - | X8: =IF($T8+$R8=2024,"2024","-") -> - | Y8: =IF($T8+$R8=2025,"2025","-") -> - | AA8: =IF($T8>2018,"Y","N") -> Y
A9: Original | B9: Retail Channels | C9: Branches | D9: Al Nakheel | E9: Branches | F9: 002 | G9: MD Business Banking | H9: Dhiraj Kunwar | I9: Saud (Naji) Mohd. | K9: Sangeetha Abraham | L9: Medium | M9: =IF(T9>2017,U9,"N/A") -> Sat | N9: Low | O9: =IF(Q9="y",1,SUMIFS('Rating Grid'!$D$11:$D$34,'Rating Grid'!$B$11:$B$34,Original!$L$30:$L$172,'Rating Grid'!$C$11:$C$34,Original!$M$30:$M$172)) -> 0 | P9: Low | Q9: N | R9: =IF(O9>S9,O9,S9) -> 0 | T9: 2019 | U9: Sat | V9: =IF($T9+$R9<=2022,"2022","-") -> 2022 | W9: =IF($T9+$R9=2023,"2023","-") -> - | X9: =IF($T9+$R9=2024,"2024","-") -> - | Y9: =IF($T9+$R9=2025,"2025","-") -> - | AA9: =IF($T9>2018,"Y","N") -> Y
A10: Original | B10: Retail Channels | C10: Branches | D10: Al Quoz | E10: Branches | F10: 035 | G10: MD Business Banking | H10: Dhiraj Kunwar | I10: Saud (Naji) Mohd. | K10: Sangeetha Abraham | L10: Medium | M10: =IF(T10>2017,U10,"N/A") -> Sat | N10: Low | O10: =IF(Q10="y",1,SUMIFS('Rating Grid'!$D$11:$D$34,'Rating Grid'!$B$11:$B$34,Original!$L$30:$L$172,'Rating Grid'!$C$11:$C$34,Original!$M$30:$M$172)) -> 0 | P10: Low | Q10: N | R10: =IF(O10>S10,O10,S10) -> 0 | T10: 2019 | U10: Sat | V10: =IF($T10+$R10<=2022,"2022","-") -> 2022 | W10: =IF($T10+$R10=2023,"2023","-") -> - | X10: =IF($T10+$R10=2024,"2024","-") -> - | Y10: =IF($T10+$R10=2025,"2025","-") -> - | AA10: =IF($T10>2018,"Y","N") -> Y
A11: Original | B11: Retail Channels | C11: Branches | D11: Al Qusais | E11: Branches | F11: 037 | G11: MD Business Banking | H11: Dhiraj Kunwar | I11: Saud (Naji) Mohd. | K11: Sangeetha Abraham | L11: Medium | M11: =IF(T11>2017,U11,"N/A") -> Sat | N11: Low | O11: =IF(Q11="y",1,SUMIFS('Rating Grid'!$D$11:$D$34,'Rating Grid'!$B$11:$B$34,Original!$L$30:$L$172,'Rating Grid'!$C$11:$C$34,Original!$M$30:$M$172)) -> 0 | P11: Low | Q11: N | R11: =IF(O11>S11,O11,S11) -> 0 | T11: 2020 | U11: Sat | V11: =IF($T11+$R11<=2022,"2022","-") -> 2022 | W11: =IF($T11+$R11=2023,"2023","-") -> - | X11: =IF($T11+$R11=2024,"2024","-") -> - | Y11: =IF($T11+$R11=2025,"2025","-") -> - | Z11: Y | AA11: =IF($T11>2018,"Y","N") -> Y | AB11: Q1 2022
A12: Original | B12: Retail Channels | C12: Branches | D12: Al Rams | E12: Branches | F12: 011 | G12: MD Business Banking | H12: Dhiraj Kunwar | I12: Saud (Naji) Mohd. | K12: Sangeetha Abraham | L12: Medium | M12: =IF(T12>2017,U12,"N/A") -> Sat | N12: Low | O12: =IF(Q12="y",1,SUMIFS('Rating Grid'!$D$11:$D$34,'Rating Grid'!$B$11:$B$34,Original!$L$30:$L$172,'Rating Grid'!$C$11:$C$34,Original!$M$30:$M$172)) -> 0 | P12: Low | Q12: N | R12: =IF(O12>S12,O12,S12) -> 0 | T12: 2019 | U12: Sat | V12: =IF($T12+$R12<=2022,"2022","-") -> 2022 | W12: =IF($T12+$R12=2023,"2023","-") -> - | X12: =IF($T12+$R12=2024,"2024","-") -> - | Y12: =IF($T12+$R12=2025,"2025","-") -> - | AA12: =IF($T12>2018,"Y","N") -> Y
A13: Original | B13: Retail Channels | C13: Branches | D13: Al Rolla | E13: Branches | F13: 057 | G13: MD Business Banking | H13: Dhiraj Kunwar | I13: Saud (Naji) Mohd. | K13: Sangeetha Abraham | L13: Medium | M13: =IF(T13>2017,U13,"N/A") -> Sat | N13: Low | O13: =IF(Q13="y",1,SUMIFS('Rating Grid'!$D$11:$D$34,'Rating Grid'!$B$11:$B$34,Original!$L$30:$L$172,'Rating Grid'!$C$11:$C$34,Original!$M$30:$M$172)) -> 0 | P13: Low | Q13: N | R13: =IF(O13>S13,O13,S13) -> 0 | T13: 2020 | U13: Sat | V13: =IF($T13+$R13<=2022,"2022","-") -> 2022 | W13: =IF($T13+$R13=2023,"2023","-") -> - | X13: =IF($T13+$R13=2024,"2024","-") -> - | Y13: =IF($T13+$R13=2025,"2025","-") -> - | AA13: =IF($T13>2018,"Y","N") -> Y
A14: Original | B14: Retail Channels | C14: Branches | D14: Deira Maktoum Street | E14: Branches | F14: 003 | G14: MD Business Banking | H14: Dhiraj Kunwar | I14: Saud (Naji) Mohd. | K14: Sangeetha Abraham | L14: Medium | M14: =IF(T14>2017,U14,"N/A") -> Sat | N14: Low | O14: =IF(Q14="y",1,SUMIFS('Rating Grid'!$D$11:$D$34,'Rating Grid'!$B$11:$B$34,Original!$L$30:$L$172,'Rating Grid'!$C$11:$C$34,Original!$M$30:$M$172)) -> 0 | P14: Low | Q14: N | R14: =IF(O14>S14,O14,S14) -> 0 | T14: 2020 | U14: Sat | V14: =IF($T14+$R14<=2022,"2022","-") -> 2022 | W14: =IF($T14+$R14=2023,"2023","-") -> - | X14: =IF($T14+$R14=2024,"2024","-") -> - | Y14: =IF($T14+$R14=2025,"2025","-") -> - | AA14: =IF($T14>2018,"Y","N") -> Y
A15: Original | B15: Retail Channels | C15: Branches | D15: Deira Souq | E15: Branches | F15: 025 | G15: MD Business Banking | H15: Dhiraj Kunwar | I15: Saud (Naji) Mohd. | K15: Sangeetha Abraham | L15: Medium | M15: =IF(T15>2017,U15,"N/A") -> Sat | N15: Low | O15: =IF(Q15="y",1,SUMIFS('Rating Grid'!$D$11:$D$34,'Rating Grid'!$B$11:$B$34,Original!$L$30:$L$172,'Rating Grid'!$C$11:$C$34,Original!$M$30:$M$172)) -> 0 | P15: Low | Q15: N | R15: =IF(O15>S15,O15,S15) -> 0 | T15: 2021 | U15: Sat | V15: =IF($T15+$R15<=2022,"2022","-") -> 2022 | W15: =IF($T15+$R15=2023,"2023","-") -> - | X15: =IF($T15+$R15=2024,"2024","-") -> - | Y15: =IF($T15+$R15=2025,"2025","-") -> - | AA15: =IF($T15>2018,"Y","N") -> Y
A16: Original | B16: Retail Channels | C16: Branches | D16: Dragon Mart | E16: Branches | F16: 088 | G16: MD Business Banking | H16: Dhiraj Kunwar | I16: Saud (Naji) Mohd. | K16: Sangeetha Abraham | L16: Medium | M16: =IF(T16>2017,U16,"N/A") -> NI | N16: Medium | O16: =IF(Q16="y",1,SUMIFS('Rating Grid'!$D$11:$D$34,'Rating Grid'!$B$11:$B$34,Original!$L$30:$L$172,'Rating Grid'!$C$11:$C$34,Original!$M$30:$M$172)) -> 0 | P16: Medium | Q16: N | R16: =IF(O16>S16,O16,S16) -> 0 | T16: 2020 | U16: NI | V16: =IF($T16+$R16<=2022,"2022","-") -> 2022 | W16: =IF($T16+$R16=2023,"2023","-") -> - | X16: =IF($T16+$R16=2024,"2024","-") -> - | Y16: =IF($T16+$R16=2025,"2025","-") -> - | AA16: =IF($T16>2018,"Y","N") -> Y
A17: Original | B17: Retail Channels | C17: Branches | D17: Emaar Business Park | E17: Branches | F17: 032 | G17: MD Business Banking | H17: Dhiraj Kunwar | I17: Saud (Naji) Mohd. | K17: Sangeetha Abraham | L17: Medium | M17: =IF(T17>2017,U17,"N/A") -> Sat | N17: Low | O17: =IF(Q17="y",1,SUMIFS('Rating Grid'!$D$11:$D$34,'Rating Grid'!$B$11:$B$34,Original!$L$30:$L$172,'Rating Grid'!$C$11:$C$34,Original!$M$30:$M$172)) -> 0 | P17: Low | Q17: N | R17: =IF(O17>S17,O17,S17) -> 0 | T17: 2020 | U17: Sat | V17: =IF($T17+$R17<=2022,"2022","-") -> 2022 | W17: =IF($T17+$R17=2023,"2023","-") -> - | X17: =IF($T17+$R17=2024,"2024","-") -> - | Y17: =IF($T17+$R17=2025,"2025","-") -> - | AA17: =IF($T17>2018,"Y","N") -> Y
A18: Original | B18: Retail Channels | C18: Branches | D18: Fujairah | E18: Branches | F18: 058 | G18: MD Business Banking | H18: Dhiraj Kunwar | I18: Saud (Naji) Mohd. | K18: Sangeetha Abraham | L18: Medium | M18: =IF(T18>2017,U18,"N/A") -> NI | N18: Low | O18: =IF(Q18="y",1,SUMIFS('Rating Grid'!$D$11:$D$34,'Rating Grid'!$B$11:$B$34,Original!$L$30:$L$172,'Rating Grid'!$C$11:$C$34,Original!$M$30:$M$172)) -> 0 | P18: Medium | Q18: N | R18: =IF(O18>S18,O18,S18) -> 0 | T18: 2019 | U18: NI | V18: =IF($T18+$R18<=2022,"2022","-") -> 2022 | W18: =IF($T18+$R18=2023,"2023","-") -> - | X18: =IF($T18+$R18=2024,"2024","-") -> - | Y18: =IF($T18+$R18=2025,"2025","-") -> - | AA18: =IF($T18>2018,"Y","N") -> Y
A19: Original | B19: Retail Channels | C19: Branches | D19: Ibn Battuta Mall | E19: Branches | F19: 029 | G19: MD Business Banking | H19: Dhiraj Kunwar | I19: Saud (Naji) Mohd. | K19: Sangeetha Abraham | L19: Medium | M19: =IF(T19>2017,U19,"N/A") -> NI | N19: Low | O19: =IF(Q19="y",1,SUMIFS('Rating Grid'!$D$11:$D$34,'Rating Grid'!$B$11:$B$34,Original!$L$30:$L$172,'Rating Grid'!$C$11:$C$34,Original!$M$30:$M$172)) -> 0 | P19: Medium | Q19: N | R19: =IF(O19>S19,O19,S19) -> 0 | T19: 2019 | U19: NI | V19: =IF($T19+$R19<=2022,"2022","-") -> 2022 | W19: =IF($T19+$R19=2023,"2023","-") -> - | X19: =IF($T19+$R19=2024,"2024","-") -> - | Y19: =IF($T19+$R19=2025,"2025","-") -> - | AA19: =IF($T19>2018,"Y","N") -> Y
A20: Original | B20: Retail Channels | C20: Branches | D20: Kalba | E20: Branches | F20: 007 | G20: MD Business Banking | H20: Dhiraj Kunwar | I20: Saud (Naji) Mohd. | K20: Sangeetha Abraham | L20: Medium | M20: =IF(T20>2017,U20,"N/A") -> NI | N20: Low | O20: =IF(Q20="y",1,SUMIFS('Rating Grid'!$D$11:$D$34,'Rating Grid'!$B$11:$B$34,Original!$L$30:$L$172,'Rating Grid'!$C$11:$C$34,Original!$M$30:$M$172)) -> 0 | P20: Medium | Q20: N | R20: =IF(O20>S20,O20,S20) -> 0 | T20: 2021 | U20: NI | V20: =IF($T20+$R20<=2022,"2022","-") -> 2022 | W20: =IF($T20+$R20=2023,"2023","-") -> - | X20: =IF($T20+$R20=2024,"2024","-") -> - | Y20: =IF($T20+$R20=2025,"2025","-") -> - | AA20: =IF($T20>2018,"Y","N") -> Y
A21: Original | B21: Retail Channels | C21: Branches | D21: Khalidiya | E21: Branches | F21: 030 | G21: MD Business Banking | H21: Dhiraj Kunwar | I21: Saud (Naji) Mohd. | K21: Sangeetha Abraham | L21: Medium | M21: =IF(T21>2017,U21,"N/A") -> NI | N21: Low | O21: =IF(Q21="y",1,SUMIFS('Rating Grid'!$D$11:$D$34,'Rating Grid'!$B$11:$B$34,Original!$L$30:$L$172,'Rating Grid'!$C$11:$C$34,Original!$M$30:$M$172)) -> 0 | P21: Medium | Q21: N | R21: =IF(O21>S21,O21,S21) -> 0 | T21: 2021 | U21: NI | V21: =IF($T21+$R21<=2022,"2022","-") -> 2022 | W21: =IF($T21+$R21=2023,"2023","-") -> - | X21: =IF($T21+$R21=2024,"2024","-") -> - | Y21: =IF($T21+$R21=2025,"2025","-") -> - | AA21: =IF($T21>2018,"Y","N") -> Y
A22: Original | B22: Retail Channels | C22: Branches | D22: King Faisal Street | E22: Branches | F22: 024 | G22: MD Business Banking | H22: Dhiraj Kunwar | I22: Saud (Naji) Mohd. | K22: Sangeetha Abraham | L22: Medium | M22: =IF(T22>2017,U22,"N/A") -> Sat | N22: Low | O22: =IF(Q22="y",1,SUMIFS('Rating Grid'!$D$11:$D$34,'Rating Grid'!$B$11:$B$34,Original!$L$30:$L$172,'Rating Grid'!$C$11:$C$34,Original!$M$30:$M$172)) -> 0 | P22: Low | Q22: N | R22: =IF(O22>S22,O22,S22) -> 0 | T22: 2019 | U22: Sat | V22: =IF($T22+$R22<=2022,"2022","-") -> 2022 | W22: =IF($T22+$R22=2023,"2023","-") -> - | X22: =IF($T22+$R22=2024,"2024","-") -> - | Y22: =IF($T22+$R22=2025,"2025","-") -> - | AA22: =IF($T22>2018,"Y","N") -> Y
A23: Original | B23: Retail Channels | C23: Branches | D23: Motor City | E23: Branches | F23: 033 | G23: MD Business Banking | H23: Dhiraj Kunwar | I23: Saud (Naji) Mohd. | K23: Sangeetha Abraham | L23: Medium | M23: =IF(T23>2017,U23,"N/A") -> Sat | N23: Low | O23: =IF(Q23="y",1,SUMIFS('Rating Grid'!$D$11:$D$34,'Rating Grid'!$B$11:$B$34,Original!$L$30:$L$172,'Rating Grid'!$C$11:$C$34,Original!$M$30:$M$172)) -> 0 | P23: Low | Q23: N | R23: =IF(O23>S23,O23,S23) -> 0 | T23: 2021 | U23: Sat | V23: =IF($T23+$R23<=2022,"2022","-") -> 2022 | W23: =IF($T23+$R23=2023,"2023","-") -> - | X23: =IF($T23+$R23=2024,"2024","-") -> - | Y23: =IF($T23+$R23=2025,"2025","-") -> - | AA23: =IF($T23>2018,"Y","N") -> Y
... A29: Original | B29: Retail Channels | C29: Branches | D29: Umm Hurair | E29: Branches | F29: 033 | G29: MD Business Banking | H29: Dhiraj Kunwar | I29: Saud (Naji) Mohd. | K29: Sangeetha Abraham | L29: Medium | M29: =IF(T29>2017,U29,"N/A") -> Sat | N29: Medium | O29: =IF(Q29="y",1,SUMIFS('Rating Grid'!$D$11:$D$34,'Rating Grid'!$B$11:$B$34,Original!$L$30:$L$172,'Rating Grid'!$C$11:$C$34,Original!$M$30:$M$172)) -> 0 | P29: Low | Q29: N | R29: =IF(O29>S29,O29,S29) -> 0 | T29: 2021 | U29: Sat | V29: =IF($T29+$R29<=2022,"2022","-") -> 2022 | W29: =IF($T29+$R29=2023,"2023","-") -> - | X29: =IF($T29+$R29=2024,"2024","-") -> - | Y29: =IF($T29+$R29=2025,"2025","-") -> - | AA29: =IF($T29>2018,"Y","N") -> Y
A30: Original | B30: Business Banking | C30: BBG - Liabilities | D30: BBG - Liabilities | E30: Business Banking | G30: MD Business Banking | H30: Dhiraj Kunwar | I30: Sulaiman Awan | K30: Neil Jarman | L30: Medium | M30: =IF(T30>2017,U30,"N/A") -> NI | N30: Medium | O30: =IF(Q30="y",1,SUMIFS('Rating Grid'!$D$11:$D$34,'Rating Grid'!$B$11:$B$34,Original!$L$30:$L$172,'Rating Grid'!$C$11:$C$34,Original!$M$30:$M$172)) -> 3 | P30: Medium | Q30: N | R30: =IF(O30>S30,O30,S30) -> 3 | T30: 2020 | U30: NI | V30: =IF($T30+$R30<=2022,"2022","-") -> - | W30: =IF($T30+$R30=2023,"2023","-") -> 2023 | X30: =IF($T30+$R30=2024,"2024","-") -> - | Y30: =IF($T30+$R30=2025,"2025","-") -> - | AA30: =IF($T30>2018,"Y","N") -> Y
A31: Original | B31: Business Banking | C31: BBG - National & Commercial Segment | D31: BBG - National & Commercial Segment | E31: Business Banking | G31: MD Business Banking | H31: Dhiraj Kunwar | I31: Emad Ahmed | K31: Neil Jarman | L31: Medium | M31: N/A | N31: Medium | O31: =IF(Q31="y",1,SUMIFS('Rating Grid'!$D$11:$D$34,'Rating Grid'!$B$11:$B$34,Original!$L$30:$L$172,'Rating Grid'!$C$11:$C$34,Original!$M$30:$M$172)) -> 3 | P31: Medium | Q31: N | R31: =IF(O31>S31,O31,S31) -> 3 | T31: 2021 | U31: Sat | V31: =IF($T31+$R31<=2022,"2022","-") -> - | W31: =IF($T31+$R31=2023,"2023","-") -> - | X31: =IF($T31+$R31=2024,"2024","-") -> 2024 | Y31: =IF($T31+$R31=2025,"2025","-") -> - | AA31: =IF($T31>2018,"Y","N") -> Y | AB31: Commercial Audit to be deferred on a prioritisation
A32: Original | B32: Corporate Functions | C32: Corporate Governance | D32: CEO's Office (Management Committees, Oversight, Strategy, Corp Communication) | E32: Corporate Functions | F32: 702 | G32: CEO | H32: Raheel Ahmed | I32: Amel B | K32: Moez Sassi | L32: Medium | M32: =IF(T32>2017,U32,"N/A") -> Sat | N32: Medium | O32: =IF(Q32="y",1,SUMIFS('Rating Grid'!$D$11:$D$34,'Rating Grid'!$B$11:$B$34,Original!$L$30:$L$172,'Rating Grid'!$C$11:$C$34,Original!$M$30:$M$172)) -> 3 | P32: Medium | Q32: N | R32: =IF(O32>S32,O32,S32) -> 3 | T32: 2018 | U32: Sat | V32: =IF($T32+$R32<=2022,"2022","-") -> 2022 | W32: =IF($T32+$R32=2023,"2023","-") -> - | X32: =IF($T32+$R32=2024,"2024","-") -> - | Y32: =IF($T32+$R32=2025,"2025","-") -> - | Z32: Y | AA32: =IF($T32>2018,"Y","N") -> N | AB32: Action plan till 2022, strategy due for revision
A33: Addition | B33: Corporate Functions | C33: Corporate Governance | D33: Company Secretary (Governance, Board and Board Committees) | E33: Corporate Functions | G33: Chief Legal Officer | H33: Ghalia Bushnaq | I33: Imad Khalil | K33: Moez Sassi | L33: Medium | M33: =IF(T33>2017,U33,"N/A") -> Sat | N33: Medium | O33: =IF(Q33="y",1,SUMIFS('Rating Grid'!$D$11:$D$34,'Rating Grid'!$B$11:$B$34,Original!$L$30:$L$172,'Rating Grid'!$C$11:$C$34,Original!$M$30:$M$172)) -> 3 | P33: Medium | Q33: N | R33: =IF(O33>S33,O33,S33) -> 3 | T33: 2018 | U33: Sat | V33: =IF($T33+$R33<=2022,"2022","-") -> 2022 | W33: =IF($T33+$R33=2023,"2023","-") -> - | X33: =IF($T33+$R33=2024,"2024","-") -> - | Y33: =IF($T33+$R33=2025,"2025","-") -> -
A34: Original | B34: Corporate Functions | C34: Strategic Planning & Initiatives | D34: Strategy | E34: Corporate Functions | F34: 702 | G34: Chief Customer Officer | H34: Dongjun Choi | I34: Gregory Thomas | K34: Moez Sassi | L34: Medium | M34: =IF(T34>2017,U34,"N/A") -> Unrated | N34: High | O34: =IF(Q34="y",1,SUMIFS('Rating Grid'!$D$11:$D$34,'Rating Grid'!$B$11:$B$34,Original!$L$30:$L$172,'Rating Grid'!$C$11:$C$34,Original!$M$30:$M$172)) -> 2 | P34: High | Q34: N | R34: =IF(O34>S34,O34,S34) -> 2 | T34: 2020 | U34: Unrated | V34: =IF($T34+$R34<=2022,"2022","-") -> 2022 | W34: =IF($T34+$R34=2023,"2023","-") -> - | X34: =IF($T34+$R34=2024,"2024","-") -> - | Y34: =IF($T34+$R34=2025,"2025","-") -> - | Z34: Y | AA34: =IF($T34>2018,"Y","N") -> Y
A35: Original | B35: Corporate Functions | C35: Investor Relations & Corp Comms | D35: Corporate Communications | E35: Corporate Functions | F35: 702 | G35: Chief Legal Officer | H35: Ghalia Bushnaq | I35: Imad Khalil | K35: Moez Sassi | L35: Low | M35: =IF(T35>2017,U35,"N/A") -> N/A | N35: Medium | O35: =IF(Q35="y",1,SUMIFS('Rating Grid'!$D$11:$D$34,'Rating Grid'!$B$11:$B$34,Original!$L$30:$L$172,'Rating Grid'!$C$11:$C$34,Original!$M$30:$M$172)) -> 4 | P35: Low | Q35: N | R35: =IF(O35>S35,O35,S35) -> 4 | U35: - | V35: =IF($T35+$R35<=2022,"2022","-") -> 2022 | W35: =IF($T35+$R35=2023,"2023","-") -> - | X35: =IF($T35+$R35=2024,"2024","-") -> - | Y35: =IF($T35+$R35=2025,"2025","-") -> -
A36: Original | B36: Corporate Functions | C36: HR | D36: Human Resources (Emiratisation & BRF Reporting) | E36: Corporate Functions | F36: 522, 703, 715 | G36: CHRO | H36: Ahmed Yousef | I36: Ahmed / Manal Ali | K36: Sangeetha Abraham | L36: Medium | M36: =IF(T36>2017,U36,"N/A") -> Sat | N36: Low | O36: =IF(Q36="y",1,SUMIFS('Rating Grid'!$D$11:$D$34,'Rating Grid'!$B$11:$B$34,Original!$L$30:$L$172,'Rating Grid'!$C$11:$C$34,Original!$M$30:$M$172)) -> 3 | P36: Medium | Q36: N | R36: =IF(O36>S36,O36,S36) -> 3 | T36: 2021 | U36: Sat | V36: =IF($T36+$R36<=2022,"2022","-") -> - | W36: =IF($T36+$R36=2023,"2023","-") -> - | X36: =IF($T36+$R36=2024,"2024","-") -> 2024 | Y36: =IF($T36+$R36=2025,"2025","-") -> - | AA36: =IF($T36>2018,"Y","N") -> Y | AB36: Emiratisation and BRF covered in 2019. The rating is changed from NI to SAT
A37: Original | B37: Corporate Functions | C37: HR | D37: Human Resources (Learning & Development) | E37: Corporate Functions | G37: CHRO | H37: Ahmed Yousef | I37: Ahmed / Sultan | K37: Sangeetha Abraham | L37: Medium | M37: =IF(T37>2017,U37,"N/A") -> N/A | N37: Low | O37: =IF(Q37="y",1,SUMIFS('Rating Grid'!$D$11:$D$34,'Rating Grid'!$B$11:$B$34,Original!$L$30:$L$172,'Rating Grid'!$C$11:$C$34,Original!$M$30:$M$172)) -> 3 | P37: Medium | Q37: N | R37: =IF(O37>S37,O37,S37) -> 3 | T37: 2015 | U37: Sat | V37: =IF($T37+$R37<=2022,"2022","-") -> 2022 | W37: =IF($T37+$R37=2023,"2023","-") -> - | X37: =IF($T37+$R37=2024,"2024","-") -> - | Y37: =IF($T37+$R37=2025,"2025","-") -> - | AA37: =IF($T37>2018,"Y","N") -> N
A38: Original | B38: Corporate Functions | C38: HR | D38: Human Resources (Organisational Effectiveness & Business Partnership) | E38: Corporate Functions | F38: 522, 703, 715 | G38: CHRO | H38: Ahmed Yousef | I38: Ahmed / Rajive Nair | K38: Sangeetha Abraham | L38: Medium | M38: =IF(T38>2017,U38,"N/A") -> NI | N38: Low | O38: =IF(Q38="y",1,SUMIFS('Rating Grid'!$D$11:$D$34,'Rating Grid'!$B$11:$B$34,Original!$L$30:$L$172,'Rating Grid'!$C$11:$C$34,Original!$M$30:$M$172)) -> 3 | P38: Medium | Q38: N | R38: =IF(O38>S38,O38,S38) -> 3 | T38: 2021 | U38: NI | V38: =IF($T38+$R38<=2022,"2022","-") -> - | W38: =IF($T38+$R38=2023,"2023","-") -> - | X38: =IF($T38+$R38=2024,"2024","-") -> 2024 | Y38: =IF($T38+$R38=2025,"2025","-") -> - | AA38: =IF($T38>2018,"Y","N") -> Y
A39: Original | B39: Corporate Functions | C39: HR | D39: Human Resources (Reward Strategy, Remuneration, Incentives) | E39: Corporate Functions | F39: 522, 703, 715 | G39: CHRO | H39: Ahmed Yousef | I39: Ahmed / Pooja | K39: Sangeetha Abraham | L39: Medium | M39: =IF(T39>2017,U39,"N/A") -> NI | N39: Low | O39: =IF(Q39="y",1,SUMIFS('Rating Grid'!$D$11:$D$34,'Rating Grid'!$B$11:$B$34,Original!$L$30:$L$172,'Rating Grid'!$C$11:$C$34,Original!$M$30:$M$172)) -> 3 | P39: Medium | Q39: N | R39: =IF(O39>S39,O39,S39) -> 3 | T39: 2021 | U39: NI | V39: =IF($T39+$R39<=2022,"2022","-") -> - | W39: =IF($T39+$R39=2023,"2023","-") -> - | X39: =IF($T39+$R39=2024,"2024","-") -> 2024 | Y39: =IF($T39+$R39=2025,"2025","-") -> - | AA39: =IF($T39>2018,"Y","N") -> Y
A40: Original | B40: Corporate Functions | C40: HR | D40: Human Resources (Talent Acquisition & HR Services) | E40: Corporate Functions | F40: 522, 703, 715 | G40: CHRO | H40: Ahmed Yousef | I40: Ahmed / Rajive | K40: Sangeetha Abraham | L40: Medium | M40: =IF(T40>2017,U40,"N/A") -> NI | N40: Low | O40: =IF(Q40="y",1,SUMIFS('Rating Grid'!$D$11:$D$34,'Rating Grid'!$B$11:$B$34,Original!$L$30:$L$172,'Rating Grid'!$C$11:$C$34,Original!$M$30:$M$172)) -> 3 | P40: Medium | Q40: N | R40: =IF(O40>S40,O40,S40) -> 3 | T40: 2021 | U40: NI | V40: =IF($T40+$R40<=2022,"2022","-") -> - | W40: =IF($T40+$R40=2023,"2023","-") -> - | X40: =IF($T40+$R40=2024,"2024","-") -> 2024 | Y40: =IF($T40+$R40=2025,"2025","-") -> - | AA40: =IF($T40>2018,"Y","N") -> Y
A41: Original | B41: Corporate Functions | C41: Legal | D41: Legal - Advisory | E41: Corporate Functions | F41: 736 | G41: Chief Legal Officer | H41: Ghalia Bushnaq | I41: Raunaq Baid | K41: Moez Sassi | L41: Medium | M41: =IF(T41>2017,U41,"N/A") -> Sat | N41: Medium | O41: =IF(Q41="y",1,SUMIFS('Rating Grid'!$D$11:$D$34,'Rating Grid'!$B$11:$B$34,Original!$L$30:$L$172,'Rating Grid'!$C$11:$C$34,Original!$M$30:$M$172)) -> 3 | P41: Medium | Q41: N | R41: =IF(O41>S41,O41,S41) -> 3 | T41: 2021 | U41: Sat | V41: =IF($T41+$R41<=2022,"2022","-") -> - | W41: =IF($T41+$R41=2023,"2023","-") -> - | X41: =IF($T41+$R41=2024,"2024","-") -> 2024 | Y41: =IF($T41+$R41=2025,"2025","-") -> - | AA41: =IF($T41>2018,"Y","N") -> Y
A42: Original | B42: Corporate Functions | C42: Legal | D42: Legal - Litigation | E42: Corporate Functions | G42: Chief Legal Officer | H42: Ghalia Bushnaq | I42: Abdulrahman Khesro | K42: Moez Sassi | L42: Medium | M42: =IF(T42>2017,U42,"N/A") -> Sat | N42: Medium | O42: =IF(Q42="y",1,SUMIFS('Rating Grid'!$D$11:$D$34,'Rating Grid'!$B$11:$B$34,Original!$L$30:$L$172,'Rating Grid'!$C$11:$C$34,Original!$M$30:$M$172)) -> 3 | P42: Medium | Q42: N | R42: =IF(O42>S42,O42,S42) -> 3 | T42: 2021 | U42: Sat | V42: =IF($T42+$R42<=2022,"2022","-") -> - | W42: =IF($T42+$R42=2023,"2023","-") -> - | X42: =IF($T42+$R42=2024,"2024","-") -> 2024 | Y42: =IF($T42+$R42=2025,"2025","-") -> - | AA42: Y
A43: Original | B43: Corporate Functions | C43: Marketing | D43: Marketing | E43: Corporate Functions | F43: 541 | G43: Chief Customer Officer | H43: Dongjun Choi | I43: Gary XX (resigned) | K43: Sangeetha Abraham | L43: Medium | M43: =IF(T43>2017,U43,"N/A") -> NI | N43: Medium | O43: =IF(Q43="y",1,SUMIFS('Rating Grid'!$D$11:$D$34,'Rating Grid'!$B$11:$B$34,Original!$L$30:$L$172,'Rating Grid'!$C$11:$C$34,Original!$M$30:$M$172)) -> 3 | P43: Medium | Q43: N | R43: =IF(O43>S43,O43,S43) -> 4 | S43: 4 | T43: 2019 | U43: NI | V43: =IF($T43+$R43<=2022,"2022","-") -> - | W43: =IF($T43+$R43=2023,"2023","-") -> 2023 | X43: =IF($T43+$R43=2024,"2024","-") -> - | Y43: =IF($T43+$R43=2025,"2025","-") -> - | Z43: y | AA43: =IF($T43>2018,"Y","N") -> Y | AB43: Manual override to 2023.
A44: Original | B44: Corporate Functions | C44: Project Management | D44: Project Management | E44: Operations | G44: CTO | H44: Saket | I44: James | K44: Neil Jarman | L44: High | M44: =IF(T44>2017,U44,"N/A") -> Unrated | N44: Medium | O44: =IF(Q44="y",1,SUMIFS('Rating Grid'!$D$11:$D$34,'Rating Grid'!$B$11:$B$34,Original!$L$30:$L$172,'Rating Grid'!$C$11:$C$34,Original!$M$30:$M$172)) -> 1 | P44: Medium | Q44: N | R44: =IF(O44>S44,O44,S44) -> 3 | S44: 3 | T44: 2021 | U44: Unrated | V44: =IF($T44+$R44<=2022,"2022","-") -> - | W44: =IF($T44+$R44=2023,"2023","-") -> - | X44: =IF($T44+$R44=2024,"2024","-") -> 2024 | Y44: =IF($T44+$R44=2025,"2025","-") -> - | Z44: Y | AA44: =IF($T44>2018,"Y","N") -> Y | AB44: Under consideration to be conducted in 2022 - Q3/4
A45: Original | B45: Corporate Functions | C45: Service Excellence | D45: Service Excellence Unit | E45: Corporate Functions | F45: 508, 560, 726 | G45: Chief Customer Officer | H45: Dongjun Choi | I45: Lina Yahya | K45: Sangeetha Abraham | L45: Medium | M45: =IF(T45>2017,U45,"N/A") -> NI | N45: Medium | O45: =IF(Q45="y",1,SUMIFS('Rating Grid'!$D$11:$D$34,'Rating Grid'!$B$11:$B$34,Original!$L$30:$L$172,'Rating Grid'!$C$11:$C$34,Original!$M$30:$M$172)) -> 3 | P45: Medium | Q45: N | R45: =IF(O45>S45,O45,S45) -> 3 | T45: 2019 | U45: NI | V45: =IF($T45+$R45<=2022,"2022","-") -> 2022 | W45: =IF($T45+$R45=2023,"2023","-") -> - | X45: =IF($T45+$R45=2024,"2024","-") -> - | Y45: =IF($T45+$R45=2025,"2025","-") -> - | Z45: Y | AA45: =IF($T45>2018,"Y","N") -> Y | AB45: Consumer Protection Framework (2022 - 5 audits covering implementation programme)
...

Sheet Audit Universe -Audit Plan2 (2)
A1: Status | B1: Area | C1: Auditable Entity | D1: Auditable Sub - Entity | E1: Area | F1: SOL ID | G1: Accountable Exec. Role (N-1) | H1: Accountable Executive | I1: Business Owner (N-2) | J1: Business Owner (N-3) | K1: Audit Owner | L1: Inherent Risk | M1: Control Environment | N1: Calculated Residual Risk | O1: Original Audit Cycle | P1: Manually Adjusted Residual Risk | Q1: Regulatory | R1: Adjusted Audit Cycle | S1: Manual Override | T1: Last Audit Year | U1: Last Audit Rating | V1: Audit Plan 2022 | W1: Audit Plan 2023 | X1: Audit Plan 2024 | Y1: Audit Plan 2025 | Z1: In CY Audit Plan | AA1: Covered in Last 3 Years | AB1: Comments
A2: Master | B2: Retail Channels | C2: Branches | D2: All Branches | E2: Branches | G2: MD Business Banking | H2: Dhiraj Kunwar | I2: Saud (Naji) Mohd. | K2: Neil Jarman | L2: Medium | M2: NI | N2: Medium | O2: 1 | P2: Medium | Q2: Y | R2: =IF(O2>S2,O2,S2) -> 1 | T2: 2020 | U2: Sat | V2: =IF($T2+$R2<=2022,"2022","-") -> 2022 | W2: =IF($T2+$R2=2023,"2023","-") -> - | X2: =IF($T2+$R2=2024,"2024","-") -> - | Y2: =IF($T2+$R2=2025,"2025","-") -> - | AA2: =IF($T2>2018,"Y","N") -> Y
A3: Original | B3: Retail Channels | C3: Branches | D3: Ajman | E3: Branches | F3: 019 | G3: MD Business Banking | H3: Dhiraj Kunwar | I3: Saud (Naji) Mohd. | K3: Sangeetha Abraham | L3: Medium | M3: =IF(T3>2017,U3,"N/A") -> Sat | N3: Medium | O3: =IF(Q3="y",1,SUMIFS('Rating Grid'!$D$11:$D$34,'Rating Grid'!$B$11:$B$34,'Audit Universe -Audit Plan2 (2)'!$L$31:$L$173,'Rating Grid'!$C$11:$C$34,'Audit Universe -Audit Plan2 (2)'!$M$31:$M$173)) -> 0 | P3: Low | Q3: N | R3: =IF(O3>S3,O3,S3) -> 0 | T3: 2020 | U3: Sat | V3: =IF($T3+$R3<=2022,"2022","-") -> 2022 | W3: =IF($T3+$R3=2023,"2023","-") -> - | X3: =IF($T3+$R3=2024,"2024","-") -> - | Y3: =IF($T3+$R3=2025,"2025","-") -> - | AA3: =IF($T3>2018,"Y","N") -> Y
A4: Original | B4: Retail Channels | C4: Branches | D4: Al Ain | E4: Branches | F4: 014 | G4: MD Business Banking | H4: Dhiraj Kunwar | I4: Saud (Naji) Mohd. | K4: Sangeetha Abraham | L4: Medium | M4: =IF(T4>2017,U4,"N/A") -> NI | N4: Medium | O4: =IF(Q4="y",1,SUMIFS('Rating Grid'!$D$11:$D$34,'Rating Grid'!$B$11:$B$34,'Audit Universe -Audit Plan2 (2)'!$L$31:$L$173,'Rating Grid'!$C$11:$C$34,'Audit Universe -Audit Plan2 (2)'!$M$31:$M$173)) -> 0 | P4: Medium | Q4: N | R4: =IF(O4>S4,O4,S4) -> 0 | T4: 2021 | U4: NI | V4: =IF($T4+$R4<=2022,"2022","-") -> 2022 | W4: =IF($T4+$R4=2023,"2023","-") -> - | X4: =IF($T4+$R4=2024,"2024","-") -> - | Y4: =IF($T4+$R4=2025,"2025","-") -> - | AA4: =IF($T4>2018,"Y","N") -> Y
A5: Original | B5: Retail Channels | C5: Branches | D5: Al Dhait | E5: Branches | F5: 031 | G5: MD Business Banking | H5: Dhiraj Kunwar | I5: Saud (Naji) Mohd. | K5: Sangeetha Abraham | L5: Medium | M5: =IF(T5>2017,U5,"N/A") -> NI | N5: Low | O5: =IF(Q5="y",1,SUMIFS('Rating Grid'!$D$11:$D$34,'Rating Grid'!$B$11:$B$34,'Audit Universe -Audit Plan2 (2)'!$L$31:$L$173,'Rating Grid'!$C$11:$C$34,'Audit Universe -Audit Plan2 (2)'!$M$31:$M$173)) -> 0 | P5: Medium | Q5: N | R5: =IF(O5>S5,O5,S5) -> 0 | T5: 2021 | U5: NI | V5: =IF($T5+$R5<=2022,"2022","-") -> 2022 | W5: =IF($T5+$R5=2023,"2023","-") -> - | X5: =IF($T5+$R5=2024,"2024","-") -> - | Y5: =IF($T5+$R5=2025,"2025","-") -> - | AA5: =IF($T5>2018,"Y","N") -> Y
A6: Original | B6: Retail Channels | C6: Branches | D6: Al Hamra | E6: Branches | F6: 065 | G6: MD Business Banking | H6: Dhiraj Kunwar | I6: Saud (Naji) Mohd. | K6: Sangeetha Abraham | L6: Medium | M6: =IF(T6>2017,U6,"N/A") -> Sat | N6: Low | O6: =IF(Q6="y",1,SUMIFS('Rating Grid'!$D$11:$D$34,'Rating Grid'!$B$11:$B$34,'Audit Universe -Audit Plan2 (2)'!$L$31:$L$173,'Rating Grid'!$C$11:$C$34,'Audit Universe -Audit Plan2 (2)'!$M$31:$M$173)) -> 0 | P6: Low | Q6: N | R6: =IF(O6>S6,O6,S6) -> 0 | T6: 2019 | U6: Sat | V6: =IF($T6+$R6<=2022,"2022","-") -> 2022 | W6: =IF($T6+$R6=2023,"2023","-") -> - | X6: =IF($T6+$R6=2024,"2024","-") -> - | Y6: =IF($T6+$R6=2025,"2025","-") -> - | AA6: =IF($T6>2018,"Y","N") -> Y
A7: Original | B7: Retail Channels | C7: Branches | D7: Al Kharan | E7: Branches | F7: 008 | G7: MD Business Banking | H7: Dhiraj Kunwar | I7: Saud (Naji) Mohd. | K7: Sangeetha Abraham | L7: Medium | M7: =IF(T7>2017,U7,"N/A") -> NI | N7: Low | O7: =IF(Q7="y",1,SUMIFS('Rating Grid'!$D$11:$D$34,'Rating Grid'!$B$11:$B$34,'Audit Universe -Audit Plan2 (2)'!$L$31:$L$173,'Rating Grid'!$C$11:$C$34,'Audit Universe -Audit Plan2 (2)'!$M$31:$M$173)) -> 0 | P7: Medium | Q7: N | R7: =IF(O7>S7,O7,S7) -> 0 | T7: 2020 | U7: NI | V7: =IF($T7+$R7<=2022,"2022","-") -> 2022 | W7: =IF($T7+$R7=2023,"2023","-") -> - | X7: =IF($T7+$R7=2024,"2024","-") -> - | Y7: =IF($T7+$R7=2025,"2025","-") -> - | AA7: =IF($T7>2018,"Y","N") -> Y
A8: Original | B8: Retail Channels | C8: Branches | D8: Al Madinah | E8: Branches | F8: 005 | G8: MD Business Banking | H8: Dhiraj Kunwar | I8: Saud (Naji) Mohd. | K8: Sangeetha Abraham | L8: Medium | M8: =IF(T8>2017,U8,"N/A") -> NI | N8: Medium | O8: =IF(Q8="y",1,SUMIFS('Rating Grid'!$D$11:$D$34,'Rating Grid'!$B$11:$B$34,'Audit Universe -Audit Plan2 (2)'!$L$31:$L$173,'Rating Grid'!$C$11:$C$34,'Audit Universe -Audit Plan2 (2)'!$M$31:$M$173)) -> 0 | P8: Medium | Q8: N | R8: =IF(O8>S8,O8,S8) -> 0 | T8: 2020 | U8: NI | V8: =IF($T8+$R8<=2022,"2022","-") -> 2022 | W8: =IF($T8+$R8=2023,"2023","-") -> - | X8: =IF($T8+$R8=2024,"2024","-") -> - | Y8: =IF($T8+$R8=2025,"2025","-") -> - | Z8: Y | AA8: =IF($T8>2018,"Y","N") -> Y | AB8: Q1 2022 Branch Closed
A9: Original | B9: Retail Channels | C9: Branches | D9: Al Mannai | E9: Branches | F9: 016 | G9: MD Business Banking | H9: Dhiraj Kunwar | I9: Saud (Naji) Mohd. | K9: Sangeetha Abraham | L9: Medium | M9: =IF(T9>2017,U9,"N/A") -> NI | N9: Low | O9: =IF(Q9="y",1,SUMIFS('Rating Grid'!$D$11:$D$34,'Rating Grid'!$B$11:$B$34,'Audit Universe -Audit Plan2 (2)'!$L$31:$L$173,'Rating Grid'!$C$11:$C$34,'Audit Universe -Audit Plan2 (2)'!$M$31:$M$173)) -> 0 | P9: Medium | Q9: N | R9: =IF(O9>S9,O9,S9) -> 0 | T9: 2021 | U9: NI | V9: =IF($T9+$R9<=2022,"2022","-") -> 2022 | W9: =IF($T9+$R9=2023,"2023","-") -> - | X9: =IF($T9+$R9=2024,"2024","-") -> - | Y9: =IF($T9+$R9=2025,"2025","-") -> - | AA9: =IF($T9>2018,"Y","N") -> Y
A10: Original | B10: Retail Channels | C10: Branches | D10: Al Nakheel | E10: Branches | F10: 002 | G10: MD Business Banking | H10: Dhiraj Kunwar | I10: Saud (Naji) Mohd. | K10: Sangeetha Abraham | L10: Medium | M10: =IF(T10>2017,U10,"N/A") -> Sat | N10: Low | O10: =IF(Q10="y",1,SUMIFS('Rating Grid'!$D$11:$D$34,'Rating Grid'!$B$11:$B$34,'Audit Universe -Audit Plan2 (2)'!$L$31:$L$173,'Rating Grid'!$C$11:$C$34,'Audit Universe -Audit Plan2 (2)'!$M$31:$M$173)) -> 0 | P10: Low | Q10: N | R10: =IF(O10>S10,O10,S10) -> 0 | T10: 2019 | U10: Sat | V10: =IF($T10+$R10<=2022,"2022","-") -> 2022 | W10: =IF($T10+$R10=2023,"2023","-") -> - | X10: =IF($T10+$R10=2024,"2024","-") -> - | Y10: =IF($T10+$R10=2025,"2025","-") -> - | AA10: =IF($T10>2018,"Y","N") -> Y
A11: Original | B11: Retail Channels | C11: Branches | D11: Al Quoz | E11: Branches | F11: 035 | G11: MD Business Banking | H11: Dhiraj Kunwar | I11: Saud (Naji) Mohd. | K11: Sangeetha Abraham | L11: Medium | M11: =IF(T11>2017,U11,"N/A") -> Sat | N11: Low | O11: =IF(Q11="y",1,SUMIFS('Rating Grid'!$D$11:$D$34,'Rating Grid'!$B$11:$B$34,'Audit Universe -Audit Plan2 (2)'!$L$31:$L$173,'Rating Grid'!$C$11:$C$34,'Audit Universe -Audit Plan2 (2)'!$M$31:$M$173)) -> 0 | P11: Low | Q11: N | R11: =IF(O11>S11,O11,S11) -> 0 | T11: 2019 | U11: Sat | V11: =IF($T11+$R11<=2022,"2022","-") -> 2022 | W11: =IF($T11+$R11=2023,"2023","-") -> - | X11: =IF($T11+$R11=2024,"2024","-") -> - | Y11: =IF($T11+$R11=2025,"2025","-") -> - | AA11: =IF($T11>2018,"Y","N") -> Y
A12: Original | B12: Retail Channels | C12: Branches | D12: Al Qusais | E12: Branches | F12: 037 | G12: MD Business Banking | H12: Dhiraj Kunwar | I12: Saud (Naji) Mohd. | K12: Sangeetha Abraham | L12: Medium | M12: =IF(T12>2017,U12,"N/A") -> Sat | N12: Low | O12: =IF(Q12="y",1,SUMIFS('Rating Grid'!$D$11:$D$34,'Rating Grid'!$B$11:$B$34,'Audit Universe -Audit Plan2 (2)'!$L$31:$L$173,'Rating Grid'!$C$11:$C$34,'Audit Universe -Audit Plan2 (2)'!$M$31:$M$173)) -> 0 | P12: Low | Q12: N | R12: =IF(O12>S12,O12,S12) -> 0 | T12: 2020 | U12: Sat | V12: =IF($T12+$R12<=2022,"2022","-") -> 2022 | W12: =IF($T12+$R12=2023,"2023","-") -> - | X12: =IF($T12+$R12=2024,"2024","-") -> - | Y12: =IF($T12+$R12=2025,"2025","-") -> - | Z12: Y | AA12: =IF($T12>2018,"Y","N") -> Y | AB12: Q1 2022
A13: Original | B13: Retail Channels | C13: Branches | D13: Al Rams | E13: Branches | F13: 011 | G13: MD Business Banking | H13: Dhiraj Kunwar | I13: Saud (Naji) Mohd. | K13: Sangeetha Abraham | L13: Medium | M13: =IF(T13>2017,U13,"N/A") -> Sat | N13: Low | O13: =IF(Q13="y",1,SUMIFS('Rating Grid'!$D$11:$D$34,'Rating Grid'!$B$11:$B$34,'Audit Universe -Audit Plan2 (2)'!$L$31:$L$173,'Rating Grid'!$C$11:$C$34,'Audit Universe -Audit Plan2 (2)'!$M$31:$M$173)) -> 0 | P13: Low | Q13: N | R13: =IF(O13>S13,O13,S13) -> 0 | T13: 2019 | U13: Sat | V13: =IF($T13+$R13<=2022,"2022","-") -> 2022 | W13: =IF($T13+$R13=2023,"2023","-") -> - | X13: =IF($T13+$R13=2024,"2024","-") -> - | Y13: =IF($T13+$R13=2025,"2025","-") -> - | AA13: =IF($T13>2018,"Y","N") -> Y | AB13: Branch Closed
A14: Original | B14: Retail Channels | C14: Branches | D14: Al Rolla | E14: Branches | F14: 057 | G14: MD Business Banking | H14: Dhiraj Kunwar | I14: Saud (Naji) Mohd. | K14: Sangeetha Abraham | L14: Medium | M14: =IF(T14>2017,U14,"N/A") -> Sat | N14: Low | O14: =IF(Q14="y",1,SUMIFS('Rating Grid'!$D$11:$D$34,'Rating Grid'!$B$11:$B$34,'Audit Universe -Audit Plan2 (2)'!$L$31:$L$173,'Rating Grid'!$C$11:$C$34,'Audit Universe -Audit Plan2 (2)'!$M$31:$M$173)) -> 0 | P14: Low | Q14: N | R14: =IF(O14>S14,O14,S14) -> 0 | T14: 2020 | U14: Sat | V14: =IF($T14+$R14<=2022,"2022","-") -> 2022 | W14: =IF($T14+$R14=2023,"2023","-") -> - | X14: =IF($T14+$R14=2024,"2024","-") -> - | Y14: =IF($T14+$R14=2025,"2025","-") -> - | AA14: =IF($T14>2018,"Y","N") -> Y
A15: Original | B15: Retail Channels | C15: Branches | D15: Deira Maktoum Street | E15: Branches | F15: 003 | G15: MD Business Banking | H15: Dhiraj Kunwar | I15: Saud (Naji) Mohd. | K15: Sangeetha Abraham | L15: Medium | M15: =IF(T15>2017,U15,"N/A") -> Sat | N15: Low | O15: =IF(Q15="y",1,SUMIFS('Rating Grid'!$D$11:$D$34,'Rating Grid'!$B$11:$B$34,'Audit Universe -Audit Plan2 (2)'!$L$31:$L$173,'Rating Grid'!$C$11:$C$34,'Audit Universe -Audit Plan2 (2)'!$M$31:$M$173)) -> 0 | P15: Low | Q15: N | R15: =IF(O15>S15,O15,S15) -> 0 | T15: 2020 | U15: Sat | V15: =IF($T15+$R15<=2022,"2022","-") -> 2022 | W15: =IF($T15+$R15=2023,"2023","-") -> - | X15: =IF($T15+$R15=2024,"2024","-") -> - | Y15: =IF($T15+$R15=2025,"2025","-") -> - | AA15: =IF($T15>2018,"Y","N") -> Y
A16: Original | B16: Retail Channels | C16: Branches | D16: Deira Souq | E16: Branches | F16: 025 | G16: MD Business Banking | H16: Dhiraj Kunwar | I16: Saud (Naji) Mohd. | K16: Sangeetha Abraham | L16: Medium | M16: =IF(T16>2017,U16,"N/A") -> Sat | N16: Low | O16: =IF(Q16="y",1,SUMIFS('Rating Grid'!$D$11:$D$34,'Rating Grid'!$B$11:$B$34,'Audit Universe -Audit Plan2 (2)'!$L$31:$L$173,'Rating Grid'!$C$11:$C$34,'Audit Universe -Audit Plan2 (2)'!$M$31:$M$173)) -> 0 | P16: Low | Q16: N | R16: =IF(O16>S16,O16,S16) -> 0 | T16: 2021 | U16: Sat | V16: =IF($T16+$R16<=2022,"2022","-") -> 2022 | W16: =IF($T16+$R16=2023,"2023","-") -> - | X16: =IF($T16+$R16=2024,"2024","-") -> - | Y16: =IF($T16+$R16=2025,"2025","-") -> - | AA16: =IF($T16>2018,"Y","N") -> Y
A17: Original | B17: Retail Channels | C17: Branches | D17: Dragon Mart | E17: Branches | F17: 088 | G17: MD Business Banking | H17: Dhiraj Kunwar | I17: Saud (Naji) Mohd. | K17: Sangeetha Abraham | L17: Medium | M17: =IF(T17>2017,U17,"N/A") -> NI | N17: Medium | O17: =IF(Q17="y",1,SUMIFS('Rating Grid'!$D$11:$D$34,'Rating Grid'!$B$11:$B$34,'Audit Universe -Audit Plan2 (2)'!$L$31:$L$173,'Rating Grid'!$C$11:$C$34,'Audit Universe -Audit Plan2 (2)'!$M$31:$M$173)) -> 0 | P17: Medium | Q17: N | R17: =IF(O17>S17,O17,S17) -> 0 | T17: 2020 | U17: NI | V17: =IF($T17+$R17<=2022,"2022","-") -> 2022 | W17: =IF($T17+$R17=2023,"2023","-") -> - | X17: =IF($T17+$R17=2024,"2024","-") -> - | Y17: =IF($T17+$R17=2025,"2025","-") -> - | AA17: =IF($T17>2018,"Y","N") -> Y
A18: Original | B18: Retail Channels | C18: Branches | D18: Emaar Business Park | E18: Branches | F18: 032 | G18: MD Business Banking | H18: Dhiraj Kunwar | I18: Saud (Naji) Mohd. | K18: Sangeetha Abraham | L18: Medium | M18: =IF(T18>2017,U18,"N/A") -> Sat | N18: Low | O18: =IF(Q18="y",1,SUMIFS('Rating Grid'!$D$11:$D$34,'Rating Grid'!$B$11:$B$34,'Audit Universe -Audit Plan2 (2)'!$L$31:$L$173,'Rating Grid'!$C$11:$C$34,'Audit Universe -Audit Plan2 (2)'!$M$31:$M$173)) -> 0 | P18: Low | Q18: N | R18: =IF(O18>S18,O18,S18) -> 0 | T18: 2020 | U18: Sat | V18: =IF($T18+$R18<=2022,"2022","-") -> 2022 | W18: =IF($T18+$R18=2023,"2023","-") -> - | X18: =IF($T18+$R18=2024,"2024","-") -> - | Y18: =IF($T18+$R18=2025,"2025","-") -> - | AA18: =IF($T18>2018,"Y","N") -> Y
A19: Original | B19: Retail Channels | C19: Branches | D19: Fujairah | E19: Branches | F19: 058 | G19: MD Business Banking | H19: Dhiraj Kunwar | I19: Saud (Naji) Mohd. | K19: Sangeetha Abraham | L19: Medium | M19: =IF(T19>2017,U19,"N/A") -> NI | N19: Low | O19: =IF(Q19="y",1,SUMIFS('Rating Grid'!$D$11:$D$34,'Rating Grid'!$B$11:$B$34,'Audit Universe -Audit Plan2 (2)'!$L$31:$L$173,'Rating Grid'!$C$11:$C$34,'Audit Universe -Audit Plan2 (2)'!$M$31:$M$173)) -> 0 | P19: Medium | Q19: N | R19: =IF(O19>S19,O19,S19) -> 0 | T19: 2019 | U19: NI | V19: =IF($T19+$R19<=2022,"2022","-") -> 2022 | W19: =IF($T19+$R19=2023,"2023","-") -> - | X19: =IF($T19+$R19=2024,"2024","-") -> - | Y19: =IF($T19+$R19=2025,"2025","-") -> - | AA19: =IF($T19>2018,"Y","N") -> Y
A20: Original | B20: Retail Channels | C20: Branches | D20: Ibn Battuta Mall | E20: Branches | F20: 029 | G20: MD Business Banking | H20: Dhiraj Kunwar | I20: Saud (Naji) Mohd. | K20: Sangeetha Abraham | L20: Medium | M20: =IF(T20>2017,U20,"N/A") -> NI | N20: Low | O20: =IF(Q20="y",1,SUMIFS('Rating Grid'!$D$11:$D$34,'Rating Grid'!$B$11:$B$34,'Audit Universe -Audit Plan2 (2)'!$L$31:$L$173,'Rating Grid'!$C$11:$C$34,'Audit Universe -Audit Plan2 (2)'!$M$31:$M$173)) -> 0 | P20: Medium | Q20: N | R20: =IF(O20>S20,O20,S20) -> 0 | T20: 2019 | U20: NI | V20: =IF($T20+$R20<=2022,"2022","-") -> 2022 | W20: =IF($T20+$R20=2023,"2023","-") -> - | X20: =IF($T20+$R20=2024,"2024","-") -> - | Y20: =IF($T20+$R20=2025,"2025","-") -> - | AA20: =IF($T20>2018,"Y","N") -> Y | AB20: Branch Closed
A21: Original | B21: Retail Channels | C21: Branches | D21: Kalba | E21: Branches | F21: 007 | G21: MD Business Banking | H21: Dhiraj Kunwar | I21: Saud (Naji) Mohd. | K21: Sangeetha Abraham | L21: Medium | M21: =IF(T21>2017,U21,"N/A") -> NI | N21: Low | O21: =IF(Q21="y",1,SUMIFS('Rating Grid'!$D$11:$D$34,'Rating Grid'!$B$11:$B$34,'Audit Universe -Audit Plan2 (2)'!$L$31:$L$173,'Rating Grid'!$C$11:$C$34,'Audit Universe -Audit Plan2 (2)'!$M$31:$M$173)) -> 0 | P21: Medium | Q21: N | R21: =IF(O21>S21,O21,S21) -> 0 | T21: 2021 | U21: NI | V21: =IF($T21+$R21<=2022,"2022","-") -> 2022 | W21: =IF($T21+$R21=2023,"2023","-") -> - | X21: =IF($T21+$R21=2024,"2024","-") -> - | Y21: =IF($T21+$R21=2025,"2025","-") -> - | AA21: =IF($T21>2018,"Y","N") -> Y | AB21: Branch Closed
A22: Original | B22: Retail Channels | C22: Branches | D22: Khalidiya | E22: Branches | F22: 030 | G22: MD Business Banking | H22: Dhiraj Kunwar | I22: Saud (Naji) Mohd. | K22: Sangeetha Abraham | L22: Medium | M22: =IF(T22>2017,U22,"N/A") -> NI | N22: Low | O22: =IF(Q22="y",1,SUMIFS('Rating Grid'!$D$11:$D$34,'Rating Grid'!$B$11:$B$34,'Audit Universe -Audit Plan2 (2)'!$L$31:$L$173,'Rating Grid'!$C$11:$C$34,'Audit Universe -Audit Plan2 (2)'!$M$31:$M$173)) -> 0 | P22: Medium | Q22: N | R22: =IF(O22>S22,O22,S22) -> 0 | T22: 2021 | U22: NI | V22: =IF($T22+$R22<=2022,"2022","-") -> 2022 | W22: =IF($T22+$R22=2023,"2023","-") -> - | X22: =IF($T22+$R22=2024,"2024","-") -> - | Y22: =IF($T22+$R22=2025,"2025","-") -> - | AA22: =IF($T22>2018,"Y","N") -> Y
A23: Original | B23: Retail Channels | C23: Branches | D23: King Faisal Street | E23: Branches | F23: 024 | G23: MD Business Banking | H23: Dhiraj Kunwar | I23: Saud (Naji) Mohd. | K23: Sangeetha Abraham | L23: Medium | M23: =IF(T23>2017,U23,"N/A") -> Sat | N23: Low | O23: =IF(Q23="y",1,SUMIFS('Rating Grid'!$D$11:$D$34,'Rating Grid'!$B$11:$B$34,'Audit Universe -Audit Plan2 (2)'!$L$31:$L$173,'Rating Grid'!$C$11:$C$34,'Audit Universe -Audit Plan2 (2)'!$M$31:$M$173)) -> 0 | P23: Low | Q23: N | R23: =IF(O23>S23,O23,S23) -> 0 | T23: 2019 | U23: Sat | V23: =IF($T23+$R23<=2022,"2022","-") -> 2022 | W23: =IF($T23+$R23=2023,"2023","-") -> - | X23: =IF($T23+$R23=2024,"2024","-") -> - | Y23: =IF($T23+$R23=2025,"2025","-") -> - | AA23: =IF($T23>2018,"Y","N") -> Y
A24: Original | B24: Retail Channels | C24: Branches | D24: Motor City | E24: Branches | F24: 033 | G24: MD Business Banking | H24: Dhiraj Kunwar | I24: Saud (Naji) Mohd. | K24: Sangeetha Abraham | L24: Medium | M24: =IF(T24>2017,U24,"N/A") -> Sat | N24: Low | O24: =IF(Q24="y",1,SUMIFS('Rating Grid'!$D$11:$D$34,'Rating Grid'!$B$11:$B$34,'Audit Universe -Audit Plan2 (2)'!$L$31:$L$173,'Rating Grid'!$C$11:$C$34,'Audit Universe -Audit Plan2 (2)'!$M$31:$M$173)) -> 0 | P24: Low | Q24: N | R24: =IF(O24>S24,O24,S24) -> 0 | T24: 2021 | U24: Sat | V24: =IF($T24+$R24<=2022,"2022","-") -> 2022 | W24: =IF($T24+$R24=2023,"2023","-") -> - | X24: =IF($T24+$R24=2024,"2024","-") -> - | Y24: =IF($T24+$R24=2025,"2025","-") -> - | AA24: =IF($T24>2018,"Y","N") -> Y
A25: Original | B25: Retail Channels | C25: Branches | D25: Mussafah | E25: Branches | F25: 039 | G25: MD Business Banking | H25: Dhiraj Kunwar | I25: Saud (Naji) Mohd. | K25: Sangeetha Abraham | L25: Medium | M25: =IF(T25>2017,U25,"N/A") -> NI | N25: Low | O25: =IF(Q25="y",1,SUMIFS('Rating Grid'!$D$11:$D$34,'Rating Grid'!$B$11:$B$34,'Audit Universe -Audit Plan2 (2)'!$L$31:$L$173,'Rating Grid'!$C$11:$C$34,'Audit Universe -Audit Plan2 (2)'!$M$31:$M$173)) -> 0 | P25: Medium | Q25: N | R25: =IF(O25>S25,O25,S25) -> 0 | T25: 2021 | U25: NI | V25: =IF($T25+$R25<=2022,"2022","-") -> 2022 | W25: =IF($T25+$R25=2023,"2023","-") -> - | X25: =IF($T25+$R25=2024,"2024","-") -> - | Y25: =IF($T25+$R25=2025,"2025","-") -> - | AA25: =IF($T25>2018,"Y","N") -> Y
A26: Original | B26: Retail Channels | C26: Branches | D26: Oud Metha | E26: Branches | F26: 018 | G26: MD Business Banking | H26: Dhiraj Kunwar | I26: Saud (Naji) Mohd. | K26: Sangeetha Abraham | L26: Medium | M26: =IF(T26>2017,U26,"N/A") -> Sat | N26: Low | O26: =IF(Q26="y",1,SUMIFS('Rating Grid'!$D$11:$D$34,'Rating Grid'!$B$11:$B$34,'Audit Universe -Audit Plan2 (2)'!$L$31:$L$173,'Rating Grid'!$C$11:$C$34,'Audit Universe -Audit Plan2 (2)'!$M$31:$M$173)) -> 0 | P26: Low | Q26: N | R26: =IF(O26>S26,O26,S26) -> 0 | T26: 2021 | U26: Sat | V26: =IF($T26+$R26<=2022,"2022","-") -> 2022 | W26: =IF($T26+$R26=2023,"2023","-") -> - | X26: =IF($T26+$R26=2024,"2024","-") -> - | Y26: =IF($T26+$R26=2025,"2025","-") -> - | AA26: =IF($T26>2018,"Y","N") -> Y | AB26: Branch Closed
A27: Original | B27: Retail Channels | C27: Branches | D27: Shaam | E27: Branches | F27: 006 | G27: MD Business Banking | H27: Dhiraj Kunwar | I27: Saud (Naji) Mohd. | K27: Sangeetha Abraham | L27: Medium | M27: =IF(T27>2017,U27,"N/A") -> Sat | N27: Low | O27: =IF(Q27="y",1,SUMIFS('Rating Grid'!$D$11:$D$34,'Rating Grid'!$B$11:$B$34,'Audit Universe -Audit Plan2 (2)'!$L$31:$L$173,'Rating Grid'!$C$11:$C$34,'Audit Universe -Audit Plan2 (2)'!$M$31:$M$173)) -> 0 | P27: Low | Q27: N | R27: =IF(O27>S27,O27,S27) -> 0 | T27: 2019 | U27: Sat | V27: =IF($T27+$R27<=2022,"2022","-") -> 2022 | W27: =IF($T27+$R27=2023,"2023","-") -> - | X27: =IF($T27+$R27=2024,"2024","-") -> - | Y27: =IF($T27+$R27=2025,"2025","-") -> - | AA27: =IF($T27>2018,"Y","N") -> Y
A28: Original | B28: Retail Channels | C28: Branches | D28: Shaikh Zayed Road | E28: Branches | F28: 012 | G28: MD Business Banking | H28: Dhiraj Kunwar | I28: Saud (Naji) Mohd. | K28: Sangeetha Abraham | L28: Medium | M28: =IF(T28>2017,U28,"N/A") -> Sat | N28: Low | O28: =IF(Q28="y",1,SUMIFS('Rating Grid'!$D$11:$D$34,'Rating Grid'!$B$11:$B$34,'Audit Universe -Audit Plan2 (2)'!$L$31:$L$173,'Rating Grid'!$C$11:$C$34,'Audit Universe -Audit Plan2 (2)'!$M$31:$M$173)) -> 0 | P28: Low | Q28: N | R28: =IF(O28>S28,O28,S28) -> 0 | T28: 2019 | U28: Sat | V28: =IF($T28+$R28<=2022,"2022","-") -> 2022 | W28: =IF($T28+$R28=2023,"2023","-") -> - | X28: =IF($T28+$R28=2024,"2024","-") -> - | Y28: =IF($T28+$R28=2025,"2025","-") -> - | AA28: =IF($T28>2018,"Y","N") -> Y | AB28: Branch Closed
A29: Original | B29: Retail Channels | C29: Branches | D29: Tourist Club | E29: Branches | F29: 004 | G29: MD Business Banking | H29: Dhiraj Kunwar | I29: Saud (Naji) Mohd. | K29: Sangeetha Abraham | L29: Medium | M29: =IF(T29>2017,U29,"N/A") -> NI | N29: Low | O29: =IF(Q29="y",1,SUMIFS('Rating Grid'!$D$11:$D$34,'Rating Grid'!$B$11:$B$34,'Audit Universe -Audit Plan2 (2)'!$L$31:$L$173,'Rating Grid'!$C$11:$C$34,'Audit Universe -Audit Plan2 (2)'!$M$31:$M$173)) -> 0 | P29: Medium | Q29: N | R29: =IF(O29>S29,O29,S29) -> 0 | T29: 2021 | U29: NI | V29: =IF($T29+$R29<=2022,"2022","-") -> 2022 | W29: =IF($T29+$R29=2023,"2023","-") -> - | X29: =IF($T29+$R29=2024,"2024","-") -> - | Y29: =IF($T29+$R29=2025,"2025","-") -> - | AA29: =IF($T29>2018,"Y","N") -> Y | AB29: Branch Closed
A30: Original | B30: Retail Channels | C30: Branches | D30: Umm Hurair | E30: Branches | F30: 033 | G30: MD Business Banking | H30: Dhiraj Kunwar | I30: Saud (Naji) Mohd. | K30: Sangeetha Abraham | L30: Medium | M30: =IF(T30>2017,U30,"N/A") -> Sat | N30: Medium | O30: =IF(Q30="y",1,SUMIFS('Rating Grid'!$D$11:$D$34,'Rating Grid'!$B$11:$B$34,'Audit Universe -Audit Plan2 (2)'!$L$31:$L$173,'Rating Grid'!$C$11:$C$34,'Audit Universe -Audit Plan2 (2)'!$M$31:$M$173)) -> 0 | P30: Low | Q30: N | R30: =IF(O30>S30,O30,S30) -> 0 | T30: 2021 | U30: Sat | V30: =IF($T30+$R30<=2022,"2022","-") -> 2022 | W30: =IF($T30+$R30=2023,"2023","-") -> - | X30: =IF($T30+$R30=2024,"2024","-") -> - | Y30: =IF($T30+$R30=2025,"2025","-") -> - | AA30: =IF($T30>2018,"Y","N") -> Y
A31: Original | B31: Business Banking | C31: BBG - Liabilities | D31: BBG - Liabilities | E31: Business Banking | G31: MD Business Banking | H31: Dhiraj Kunwar | I31: Sulaiman Awan | K31: Neil Jarman | L31: Medium | M31: =IF(T31>2017,U31,"N/A") -> NI | N31: Medium | O31: =IF(Q31="y",1,SUMIFS('Rating Grid'!$D$11:$D$34,'Rating Grid'!$B$11:$B$34,'Audit Universe -Audit Plan2 (2)'!$L$31:$L$173,'Rating Grid'!$C$11:$C$34,'Audit Universe -Audit Plan2 (2)'!$M$31:$M$173)) -> 3 | P31: Medium | Q31: N | R31: =IF(O31>S31,O31,S31) -> 3 | T31: 2020 | U31: NI | V31: =IF($T31+$R31<=2022,"2022","-") -> - | W31: =IF($T31+$R31=2023,"2023","-") -> 2023 | X31: =IF($T31+$R31=2024,"2024","-") -> - | Y31: =IF($T31+$R31=2025,"2025","-") -> - | AA31: =IF($T31>2018,"Y","N") -> Y
A32: Original | B32: Business Banking | C32: BBG - National & Commercial Segment | D32: BBG - National & Commercial Segment | E32: Business Banking | G32: MD Business Banking | H32: Dhiraj Kunwar | I32: Emad Ahmed | K32: Neil Jarman | L32: Medium | M32: N/A | N32: Medium | O32: =IF(Q32="y",1,SUMIFS('Rating Grid'!$D$11:$D$34,'Rating Grid'!$B$11:$B$34,'Audit Universe -Audit Plan2 (2)'!$L$31:$L$173,'Rating Grid'!$C$11:$C$34,'Audit Universe -Audit Plan2 (2)'!$M$31:$M$173)) -> 3 | P32: Medium | Q32: N | R32: =IF(O32>S32,O32,S32) -> 3 | T32: 2021 | U32: Sat | V32: =IF($T32+$R32<=2022,"2022","-") -> - | W32: =IF($T32+$R32=2023,"2023","-") -> - | X32: =IF($T32+$R32=2024,"2024","-") -> 2024 | Y32: =IF($T32+$R32=2025,"2025","-") -> - | AA32: =IF($T32>2018,"Y","N") -> Y | AB32: Commercial Audit to be deferred on a prioritisation
A33: Original | B33: Corporate Functions | C33: Corporate Governance | D33: CEO's Office (Management Committees, Oversight, Strategy, Corp Communication) | E33: Corporate Functions | F33: 702 | G33: CEO | H33: Raheel Ahmed | I33: Amel B | K33: Moez Sassi | L33: Medium | M33: =IF(T33>2017,U33,"N/A") -> Sat | N33: Medium | O33: =IF(Q33="y",1,SUMIFS('Rating Grid'!$D$11:$D$34,'Rating Grid'!$B$11:$B$34,'Audit Universe -Audit Plan2 (2)'!$L$31:$L$173,'Rating Grid'!$C$11:$C$34,'Audit Universe -Audit Plan2 (2)'!$M$31:$M$173)) -> 3 | P33: Medium | Q33: N | R33: =IF(O33>S33,O33,S33) -> 3 | T33: 2018 | U33: Sat | V33: =IF($T33+$R33<=2022,"2022","-") -> 2022 | W33: =IF($T33+$R33=2023,"2023","-") -> - | X33: =IF($T33+$R33=2024,"2024","-") -> - | Y33: =IF($T33+$R33=2025,"2025","-") -> - | Z33: Y | AA33: =IF($T33>2018,"Y","N") -> N | AB33: Action plan till 2022, strategy due for revision
A34: Original | B34: Corporate Functions | C34: Corporate Governance | D34: Company Secretary (Governance, Board and Board Committees) | E34: Corporate Functions | G34: Chief Legal Officer | H34: Ghalia Bushnaq | I34: Imad Khalil | K34: Moez Sassi | L34: Medium | M34: =IF(T34>2017,U34,"N/A") -> Sat | N34: Medium | O34: =IF(Q34="y",1,SUMIFS('Rating Grid'!$D$11:$D$34,'Rating Grid'!$B$11:$B$34,'Audit Universe -Audit Plan2 (2)'!$L$31:$L$173,'Rating Grid'!$C$11:$C$34,'Audit Universe -Audit Plan2 (2)'!$M$31:$M$173)) -> 3 | P34: Medium | Q34: N | R34: =IF(O34>S34,O34,S34) -> 3 | T34: 2018 | U34: Sat | V34: =IF($T34+$R34<=2022,"2022","-") -> 2022 | W34: =IF($T34+$R34=2023,"2023","-") -> - | X34: =IF($T34+$R34=2024,"2024","-") -> - | Y34: =IF($T34+$R34=2025,"2025","-") -> -
A35: Original | B35: Corporate Functions | C35: Strategic Planning & Initiatives | D35: Strategy | E35: Corporate Functions | F35: 702 | G35: Chief Customer Officer | H35: Dongjun Choi | I35: Gregory Thomas | K35: Moez Sassi | L35: Medium | M35: =IF(T35>2017,U35,"N/A") -> Unrated | N35: High | O35: =IF(Q35="y",1,SUMIFS('Rating Grid'!$D$11:$D$34,'Rating Grid'!$B$11:$B$34,'Audit Universe -Audit Plan2 (2)'!$L$31:$L$173,'Rating Grid'!$C$11:$C$34,'Audit Universe -Audit Plan2 (2)'!$M$31:$M$173)) -> 2 | P35: High | Q35: N | R35: =IF(O35>S35,O35,S35) -> 2 | T35: 2020 | U35: Unrated | V35: =IF($T35+$R35<=2022,"2022","-") -> 2022 | W35: =IF($T35+$R35=2023,"2023","-") -> - | X35: =IF($T35+$R35=2024,"2024","-") -> - | Y35: =IF($T35+$R35=2025,"2025","-") -> - | Z35: Y | AA35: =IF($T35>2018,"Y","N") -> Y
A36: Original | B36: Corporate Functions | C36: Investor Relations & Corp Comms | D36: Corporate Communications | E36: Corporate Functions | F36: 702 | G36: Chief Legal Officer | H36: Ghalia Bushnaq | I36: Imad Khalil | K36: Moez Sassi | L36: Low | M36: =IF(T36>2017,U36,"N/A") -> N/A | N36: Medium | O36: =IF(Q36="y",1,SUMIFS('Rating Grid'!$D$11:$D$34,'Rating Grid'!$B$11:$B$34,'Audit Universe -Audit Plan2 (2)'!$L$31:$L$173,'Rating Grid'!$C$11:$C$34,'Audit Universe -Audit Plan2 (2)'!$M$31:$M$173)) -> 4 | P36: Low | Q36: N | R36: =IF(O36>S36,O36,S36) -> 4 | U36: - | V36: =IF($T36+$R36<=2022,"2022","-") -> 2022 | W36: =IF($T36+$R36=2023,"2023","-") -> - | X36: =IF($T36+$R36=2024,"2024","-") -> - | Y36: =IF($T36+$R36=2025,"2025","-") -> -
A37: Original | B37: Corporate Functions | C37: HR | D37: Human Resources (Emiratisation & BRF Reporting) | E37: Corporate Functions | F37: 522, 703, 715 | G37: CHRO | H37: Ahmed Yousef | I37: Ahmed / Manal Ali | K37: Sangeetha Abraham | L37: Medium | M37: =IF(T37>2017,U37,"N/A") -> Sat | N37: Low | O37: =IF(Q37="y",1,SUMIFS('Rating Grid'!$D$11:$D$34,'Rating Grid'!$B$11:$B$34,'Audit Universe -Audit Plan2 (2)'!$L$31:$L$173,'Rating Grid'!$C$11:$C$34,'Audit Universe -Audit Plan2 (2)'!$M$31:$M$173)) -> 3 | P37: Medium | Q37: N | R37: =IF(O37>S37,O37,S37) -> 3 | T37: 2021 | U37: Sat | V37: =IF($T37+$R37<=2022,"2022","-") -> - | W37: =IF($T37+$R37=2023,"2023","-") -> - | X37: =IF($T37+$R37=2024,"2024","-") -> 2024 | Y37: =IF($T37+$R37=2025,"2025","-") -> - | AA37: =IF($T37>2018,"Y","N") -> Y | AB37: Emiratisation and BRF covered in 2019. The rating is changed from NI to SAT
A38: Original | B38: Corporate Functions | C38: HR | D38: Human Resources (Learning & Development) | E38: Corporate Functions | G38: CHRO | H38: Ahmed Yousef | I38: Ahmed / Sultan | K38: Sangeetha Abraham | L38: Medium | M38: =IF(T38>2017,U38,"N/A") -> N/A | N38: Low | O38: =IF(Q38="y",1,SUMIFS('Rating Grid'!$D$11:$D$34,'Rating Grid'!$B$11:$B$34,'Audit Universe -Audit Plan2 (2)'!$L$31:$L$173,'Rating Grid'!$C$11:$C$34,'Audit Universe -Audit Plan2 (2)'!$M$31:$M$173)) -> 3 | P38: Medium | Q38: N | R38: =IF(O38>S38,O38,S38) -> 3 | T38: 2015 | U38: Sat | V38: =IF($T38+$R38<=2022,"2022","-") -> 2022 | W38: =IF($T38+$R38=2023,"2023","-") -> - | X38: =IF($T38+$R38=2024,"2024","-") -> - | Y38: =IF($T38+$R38=2025,"2025","-") -> - | AA38: =IF($T38>2018,"Y","N") -> N
A39: Original | B39: Corporate Functions | C39: HR | D39: Human Resources (Organisational Effectiveness & Business Partnership) | E39: Corporate Functions | F39: 522, 703, 715 | G39: CHRO | H39: Ahmed Yousef | I39: Ahmed / Rajive Nair | K39: Sangeetha Abraham | L39: Medium | M39: =IF(T39>2017,U39,"N/A") -> NI | N39: Low | O39: =IF(Q39="y",1,SUMIFS('Rating Grid'!$D$11:$D$34,'Rating Grid'!$B$11:$B$34,'Audit Universe -Audit Plan2 (2)'!$L$31:$L$173,'Rating Grid'!$C$11:$C$34,'Audit Universe -Audit Plan2 (2)'!$M$31:$M$173)) -> 3 | P39: Medium | Q39: N | R39: =IF(O39>S39,O39,S39) -> 3 | T39: 2021 | U39: NI | V39: =IF($T39+$R39<=2022,"2022","-") -> - | W39: =IF($T39+$R39=2023,"2023","-") -> - | X39: =IF($T39+$R39=2024,"2024","-") -> 2024 | Y39: =IF($T39+$R39=2025,"2025","-") -> - | AA39: =IF($T39>2018,"Y","N") -> Y
A40: Original | B40: Corporate Functions | C40: HR | D40: Human Resources (Reward Strategy, Remuneration, Incentives) | E40: Corporate Functions | F40: 522, 703, 715 | G40: CHRO | H40: Ahmed Yousef | I40: Ahmed / Pooja | K40: Sangeetha Abraham | L40: Medium | M40: =IF(T40>2017,U40,"N/A") -> NI | N40: Low | O40: =IF(Q40="y",1,SUMIFS('Rating Grid'!$D$11:$D$34,'Rating Grid'!$B$11:$B$34,'Audit Universe -Audit Plan2 (2)'!$L$31:$L$173,'Rating Grid'!$C$11:$C$34,'Audit Universe -Audit Plan2 (2)'!$M$31:$M$173)) -> 3 | P40: Medium | Q40: N | R40: =IF(O40>S40,O40,S40) -> 3 | T40: 2021 | U40: NI | V40: =IF($T40+$R40<=2022,"2022","-") -> - | W40: =IF($T40+$R40=2023,"2023","-") -> - | X40: =IF($T40+$R40=2024,"2024","-") -> 2024 | Y40: =IF($T40+$R40=2025,"2025","-") -> - | AA40: =IF($T40>2018,"Y","N") -> Y
...

Sheet AU before last cleanse
A1: Status | B1: Area | C1: Auditable Entity | D1: Auditable Sub - Entity | E1: Area | F1: SOL ID | G1: Accountable Exec. Role (N-1) | H1: Accountable Executive | I1: Business Owner (N-2) | J1: Business Owner (N-3) | K1: Audit Owner | L1: Inherent Risk | M1: Control Environment | N1: Calculated Residual Risk | O1: Original Audit Cycle | P1: Manually Adjusted Residual Risk | Q1: Regulatory | R1: Adjusted Audit Cycle | S1: Manual Override | T1: Last Audit Year | U1: Last Audit Rating | V1: Audit Plan 2022 | W1: Audit Plan 2023 | X1: Audit Plan 2024 | Y1: Audit Plan 2025 | Z1: In CY Audit Plan | AA1: Covered in Last 3 Years | AB1: Comments
